<mujoco model="cable_trunk_model_example">
<option gravity="0 0 0"/>
  <compiler angle="radian"/>
  <extension>
    <plugin plugin="mujoco.elasticity.cable">
      <instance name="compositeactuated">
        <config key="twist" value="1e8"/>
        <config key="bend" value="1e8"/>
        <config key="vmax" value="0"/>
      </instance>
    </plugin>
  </extension>
  <custom>
    <text name="composite_actuated" data="rope_actuated"/>
  </custom>
  <asset>
    <texture type="2d" name="grid" builtin="checker" rgb1="0.1 0.2 0.3" rgb2="0.2 0.3 0.4" width="300" height="300"/>
    <material name="grid" texture="grid" texrepeat="8 8" reflectance="0.2"/>
  </asset>
  <worldbody>
    <geom size="10 10 0.01" type="plane" material="grid"/>
    <light pos="0 0 2" dir="0 0 -1"/>
    <body name="actuatedB_first" pos="0 0 0.7" quat="0 -0.707107 0 0.707107">
      <!-- Add slider joint with stiffness and damping to simulate elongation of material-->
      <joint name="slider_cable_world" pos="0 0 0" type="slide" axis="1 0 0" group="3" stiffness="1e2" damping="0.8"/>
      <geom name="actuatedG0" size="0.005 0.005" pos="0.005 0 0" quat="0.707107 0 -0.707107 0" type="capsule" rgba="0.8 0.2 0.1 1"/>
      <site name="actuatedS_first" pos="0 0 0" group="3"/> 
      <!-- Add sides for tendon to pass through-->
      <site name="cable_0_y_front" pos="0 0.005 0"/> 
      <site name="cable_0_y_back" pos="0 -0.005 0"/>
      <site name="cable_0_z_front" pos="0 0 0.005"/> 
      <site name="cable_0_z_back" pos="0 0 -0.005"/>
      <plugin instance="compositeactuated"/>
      <body name="actuatedB_1" pos="0.00999999 0 0">
        <joint name="actuatedJ_1" pos="0 0 0" type="ball" group="3" actuatorfrclimited="false" armature="0.01" damping="0.25"/>
        <geom name="actuatedG1" size="0.005 0.00999999" pos="0.00999999 0 0" quat="0.707107 0 -0.707107 0" type="capsule" rgba="0.8 0.2 0.1 1"/>
        <!-- Add sides for tendon to pass through-->
        <site name="cable_1_y_front" pos="0 0.005 0"/> 
        <site name="cable_1_y_back" pos="0 -0.005 0"/>
        <site name="cable_1_z_front" pos="0 0 0.005"/> 
        <site name="cable_1_z_back" pos="0 0 -0.005"/> 
        <plugin instance="compositeactuated"/>
        <body name="actuatedB_2" pos="0.02 0 0">
          <joint name="actuatedJ_2" pos="0 0 0" type="ball" group="3" actuatorfrclimited="false" armature="0.01" damping="0.25"/>
          <geom name="actuatedG2" size="0.005 0.005" pos="0.005 0 0" quat="0.707107 0 -0.707107 0" type="capsule" rgba="0.8 0.2 0.1 1"/>
          <!-- Add sides for tendon to pass through-->
          <site name="cable_2_y_front" pos="0 0.005 0"/> 
          <site name="cable_2_y_back" pos="0 -0.005 0"/>
          <site name="cable_2_z_front" pos="0 0 0.005"/> 
          <site name="cable_2_z_back" pos="0 0 -0.005"/>
          <plugin instance="compositeactuated"/>
          <body name="actuatedB_3" pos="0.00999999 0 0">
            <joint name="actuatedJ_3" pos="0 0 0" type="ball" group="3" actuatorfrclimited="false" armature="0.01" damping="0.25"/>
            <geom name="actuatedG3" size="0.005 0.00500003" pos="0.00500003 0 0" quat="0.707107 0 -0.707107 0" type="capsule" rgba="0.8 0.2 0.1 1"/>
            <!-- Add sides for tendon to pass through-->
            <site name="cable_3_y_front" pos="0 0.005 0"/> 
            <site name="cable_3_y_back" pos="0 -0.005 0"/>
            <site name="cable_3_z_front" pos="0 0 0.005"/> 
            <site name="cable_3_z_back" pos="0 0 -0.005"/> 
            <plugin instance="compositeactuated"/>
            <body name="actuatedB_4" pos="0.0100001 0 0">
              <joint name="actuatedJ_4" pos="0 0 0" type="ball" group="3" actuatorfrclimited="false" armature="0.01" damping="0.25"/>
              <!-- Add sides for tendon to pass through-->
              <site name="cable_4_y_front" pos="0 0.005 0"/> 
              <site name="cable_4_y_back" pos="0 -0.005 0"/>
              <site name="cable_4_z_front" pos="0 0 0.005"/> 
              <site name="cable_4_z_back" pos="0 0 -0.005"/> 
              <geom name="actuatedG4" size="0.005 0.005" pos="0.005 0 0" quat="0.707107 0 -0.707107 0" type="capsule" rgba="0.8 0.2 0.1 1"/>
              <plugin instance="compositeactuated"/>
              <body name="actuatedB_5" pos="0.00999999 0 0">
                <joint name="actuatedJ_5" pos="0 0 0" type="ball" group="3" actuatorfrclimited="false" armature="0.01" damping="0.25"/>
                <geom name="actuatedG5" size="0.005 0.00999999" pos="0.00999999 0 0" quat="0.707107 0 -0.707107 0" type="capsule" rgba="0.8 0.2 0.1 1"/>
                <!-- Add sides for tendon to pass through-->
                <site name="cable_5_y_front" pos="0 0.005 0"/> 
                <site name="cable_5_y_back" pos="0 -0.005 0"/>
                <site name="cable_5_z_front" pos="0 0 0.005"/> 
                <site name="cable_5_z_back" pos="0 0 -0.005"/> 
                  <plugin instance="compositeactuated"/>
                <body name="actuatedB_6" pos="0.02 0 0">
                  <joint name="actuatedJ_6" pos="0 0 0" type="ball" group="3" actuatorfrclimited="false" armature="0.01" damping="0.25"/>
                  <geom name="actuatedG6" size="0.005 0.005" pos="0.005 0 0" quat="0.707107 0 -0.707107 0" type="capsule" rgba="0.8 0.2 0.1 1"/>
                  <!-- Add sides for tendon to pass through-->
                  <site name="cable_6_y_front" pos="0 0.005 0"/> 
                  <site name="cable_6_y_back" pos="0 -0.005 0"/>
                  <site name="cable_6_z_front" pos="0 0 0.005"/> 
                  <site name="cable_6_z_back" pos="0 0 -0.005"/> 
                  <plugin instance="compositeactuated"/>
                  <body name="actuatedB_7" pos="0.00999999 0 0">
                    <joint name="actuatedJ_7" pos="0 0 0" type="ball" group="3" actuatorfrclimited="false" armature="0.01" damping="0.25"/>
                    <geom name="actuatedG7" size="0.005 0.005" pos="0.005 0 0" quat="0.707107 0 -0.707107 0" type="capsule" rgba="0.8 0.2 0.1 1"/>
                    <!-- Add sides for tendon to pass through-->
                    <site name="cable_7_y_front" pos="0 0.005 0"/> 
                    <site name="cable_7_y_back" pos="0 -0.005 0"/>
                    <site name="cable_7_z_front" pos="0 0 0.005"/> 
                    <site name="cable_7_z_back" pos="0 0 -0.005"/> 
                    <plugin instance="compositeactuated"/>
                    <body name="actuatedB_8" pos="0.00999999 0 0">
                      <joint name="actuatedJ_8" pos="0 0 0" type="ball" group="3" actuatorfrclimited="false" armature="0.01" damping="0.25"/>
                      <geom name="actuatedG8" size="0.005 0.01" pos="0.01 0 0" quat="0.707107 0 -0.707107 0" type="capsule" rgba="0.8 0.2 0.1 1"/>
                      <!-- Add sides for tendon to pass through-->
                      <site name="cable_8_y_front" pos="0 0.005 0"/> 
                      <site name="cable_8_y_back" pos="0 -0.005 0"/>
                      <site name="cable_8_z_front" pos="0 0 0.005"/> 
                      <site name="cable_8_z_back" pos="0 0 -0.005"/> 
                      <plugin instance="compositeactuated"/>
                      <body name="actuatedB_9" pos="0.02 0 0">
                        <joint name="actuatedJ_9" pos="0 0 0" type="ball" group="3" actuatorfrclimited="false" armature="0.01" damping="0.25"/>
                        <geom name="actuatedG9" size="0.005 0.005" pos="0.005 0 0" quat="0.707107 0 -0.707107 0" type="capsule" rgba="0.8 0.2 0.1 1"/>
                        <!-- Add sides for tendon to pass through-->
                        <site name="cable_9_y_front" pos="0 0.005 0"/> 
                        <site name="cable_9_y_back" pos="0 -0.005 0"/>
                        <site name="cable_9_z_front" pos="0 0 0.005"/> 
                        <site name="cable_9_z_back" pos="0 0 -0.005"/> 
                        <plugin instance="compositeactuated"/>
                        <body name="actuatedB_10" pos="0.00999999 0 0">
                          <joint name="actuatedJ_10" pos="0 0 0" type="ball" group="3" actuatorfrclimited="false" armature="0.01" damping="0.25"/>
                          <geom name="actuatedG10" size="0.005 0.005" pos="0.005 0 0" quat="0.707107 0 -0.707107 0" type="capsule" rgba="0.8 0.2 0.1 1"/>
                          <!-- Add sides for tendon to pass through-->
                          <site name="cable_10_y_front" pos="0 0.005 0"/> 
                          <site name="cable_10_y_back" pos="0 -0.005 0"/>
                          <site name="cable_10_z_front" pos="0 0 0.005"/> 
                          <site name="cable_10_z_back" pos="0 0 -0.005"/> 
                          <plugin instance="compositeactuated"/>
                          <body name="actuatedB_11" pos="0.00999999 0 0">
                            <joint name="actuatedJ_11" pos="0 0 0" type="ball" group="3" actuatorfrclimited="false" armature="0.01" damping="0.25"/>
                            <geom name="actuatedG11" size="0.005 0.005" pos="0.005 0 0" quat="0.707107 0 -0.707107 0" type="capsule" rgba="0.8 0.2 0.1 1"/>
                            <!-- Add sides for tendon to pass through-->
                            <site name="cable_11_y_front" pos="0 0.005 0"/> 
                            <site name="cable_11_y_back" pos="0 -0.005 0"/>
                            <site name="cable_11_z_front" pos="0 0 0.005"/> 
                            <site name="cable_11_z_back" pos="0 0 -0.005"/> 
                            <plugin instance="compositeactuated"/>
                            <body name="actuatedB_12" pos="0.00999999 0 0">
                              <joint name="actuatedJ_12" pos="0 0 0" type="ball" group="3" actuatorfrclimited="false" armature="0.01" damping="0.25"/>
                              <geom name="actuatedG12" size="0.005 0.01" pos="0.01 0 0" quat="0.707107 0 -0.707107 0" type="capsule" rgba="0.8 0.2 0.1 1"/>
                              <!-- Add sides for tendon to pass through-->
                              <site name="cable_12_y_front" pos="0 0.005 0"/> 
                              <site name="cable_12_y_back" pos="0 -0.005 0"/>
                              <site name="cable_12_z_front" pos="0 0 0.005"/> 
                              <site name="cable_12_z_back" pos="0 0 -0.005"/> 
                              <plugin instance="compositeactuated"/>
                              <body name="actuatedB_13" pos="0.02 0 0">
                                <joint name="actuatedJ_13" pos="0 0 0" type="ball" group="3" actuatorfrclimited="false" armature="0.01" damping="0.25"/>
                                <geom name="actuatedG13" size="0.005 0.005" pos="0.005 0 0" quat="0.707107 0 -0.707107 0" type="capsule" rgba="0.8 0.2 0.1 1"/>
                                <!-- Add sides for tendon to pass through-->
                                <site name="cable_13_y_front" pos="0 0.005 0"/> 
                                <site name="cable_13_y_back" pos="0 -0.005 0"/>
                                <site name="cable_13_z_front" pos="0 0 0.005"/> 
                                <site name="cable_13_z_back" pos="0 0 -0.005"/> 
                                <plugin instance="compositeactuated"/>
                                <body name="actuatedB_14" pos="0.00999999 0 0">
                                  <joint name="actuatedJ_14" pos="0 0 0" type="ball" group="3" actuatorfrclimited="false" armature="0.01" damping="0.25"/>
                                  <geom name="actuatedG14" size="0.005 0.005" pos="0.005 0 0" quat="0.707107 0 -0.707107 0" type="capsule" rgba="0.8 0.2 0.1 1"/>
                                  <!-- Add sides for tendon to pass through-->
                                  <site name="cable_14_y_front" pos="0 0.005 0"/> 
                                  <site name="cable_14_y_back" pos="0 -0.005 0"/>
                                  <site name="cable_14_z_front" pos="0 0 0.005"/> 
                                  <site name="cable_14_z_back" pos="0 0 -0.005"/> 
                                  <plugin instance="compositeactuated"/>
                                  <body name="actuatedB_15" pos="0.00999999 0 0">
                                    <joint name="actuatedJ_15" pos="0 0 0" type="ball" group="3" actuatorfrclimited="false" armature="0.01" damping="0.25"/>
                                    <geom name="actuatedG15" size="0.005 0.00999999" pos="0.00999999 0 0" quat="0.707107 0 -0.707107 0" type="capsule" rgba="0.8 0.2 0.1 1"/>
                                    <!-- Add sides for tendon to pass through-->
                                    <site name="cable_15_y_front" pos="0 0.005 0"/> 
                                    <site name="cable_15_y_back" pos="0 -0.005 0"/>
                                    <site name="cable_15_z_front" pos="0 0 0.005"/> 
                                    <site name="cable_15_z_back" pos="0 0 -0.005"/> 
                                    <plugin instance="compositeactuated"/>
                                    <body name="actuatedB_16" pos="0.02 0 0">
                                      <joint name="actuatedJ_16" pos="0 0 0" type="ball" group="3" actuatorfrclimited="false" armature="0.01" damping="0.25"/>
                                      <geom name="actuatedG16" size="0.005 0.00500001" pos="0.00500001 0 0" quat="0.707107 0 -0.707107 0" type="capsule" rgba="0.8 0.2 0.1 1"/>
                                      <!-- Add sides for tendon to pass through-->
                                      <site name="cable_16_y_front" pos="0 0.005 0"/> 
                                      <site name="cable_16_y_back" pos="0 -0.005 0"/>
                                      <site name="cable_16_z_front" pos="0 0 0.005"/> 
                                      <site name="cable_16_z_back" pos="0 0 -0.005"/> 
                                      <plugin instance="compositeactuated"/>
                                      <body name="actuatedB_17" pos="0.01 0 0">
                                        <joint name="actuatedJ_17" pos="0 0 0" type="ball" group="3" actuatorfrclimited="false" armature="0.01" damping="0.25"/>
                                        <geom name="actuatedG17" size="0.005 0.005" pos="0.005 0 0" quat="0.707107 0 -0.707107 0" type="capsule" rgba="0.8 0.2 0.1 1"/>
                                        <!-- Add sides for tendon to pass through-->
                                        <site name="cable_17_y_front" pos="0 0.005 0"/> 
                                        <site name="cable_17_y_back" pos="0 -0.005 0"/>
                                        <site name="cable_17_z_front" pos="0 0 0.005"/> 
                                        <site name="cable_17_z_back" pos="0 0 -0.005"/> 
                                        <plugin instance="compositeactuated"/>
                                        <body name="actuatedB_18" pos="0.00999999 0 0">
                                          <joint name="actuatedJ_18" pos="0 0 0" type="ball" group="3" actuatorfrclimited="false" armature="0.01" damping="0.25"/>
                                          <geom name="actuatedG18" size="0.005 0.005" pos="0.005 0 0" quat="0.707107 0 -0.707107 0" type="capsule" rgba="0.8 0.2 0.1 1"/>
                                          <!-- Add sides for tendon to pass through-->
                                          <site name="cable_18_y_front" pos="0 0.005 0"/> 
                                          <site name="cable_18_y_back" pos="0 -0.005 0"/>
                                          <site name="cable_18_z_front" pos="0 0 0.005"/> 
                                          <site name="cable_18_z_back" pos="0 0 -0.005"/> 
                                          <plugin instance="compositeactuated"/>
                                          <body name="actuatedB_19" pos="0.00999999 0 0">
                                            <joint name="actuatedJ_19" pos="0 0 0" type="ball" group="3" actuatorfrclimited="false" armature="0.01" damping="0.25"/>
                                            <geom name="actuatedG19" size="0.005 0.01" pos="0.01 0 0" quat="0.707107 0 -0.707107 0" type="capsule" rgba="0.8 0.2 0.1 1"/>
                                            <!-- Add sides for tendon to pass through-->
                                            <site name="cable_19_y_front" pos="0 0.005 0"/> 
                                            <site name="cable_19_y_back" pos="0 -0.005 0"/>
                                            <site name="cable_19_z_front" pos="0 0 0.005"/> 
                                            <site name="cable_19_z_back" pos="0 0 -0.005"/> 
                                            <plugin instance="compositeactuated"/>
                                            <body name="actuatedB_20" pos="0.02 0 0">
                                              <joint name="actuatedJ_20" pos="0 0 0" type="ball" group="3" actuatorfrclimited="false" armature="0.01" damping="0.25"/>
                                              <geom name="actuatedG20" size="0.005 0.005" pos="0.005 0 0" quat="0.707107 0 -0.707107 0" type="capsule" rgba="0.8 0.2 0.1 1"/>
                                              <!-- Add sides for tendon to pass through-->
                                              <site name="cable_20_y_front" pos="0 0.005 0"/> 
                                              <site name="cable_20_y_back" pos="0 -0.005 0"/>
                                              <site name="cable_20_z_front" pos="0 0 0.005"/> 
                                              <site name="cable_20_z_back" pos="0 0 -0.005"/> 
                                              <plugin instance="compositeactuated"/>
                                              <body name="actuatedB_21" pos="0.00999999 0 0">
                                                <joint name="actuatedJ_21" pos="0 0 0" type="ball" group="3" actuatorfrclimited="false" armature="0.01" damping="0.25"/>
                                                <geom name="actuatedG21" size="0.005 0.00500001" pos="0.00500001 0 0" quat="0.707107 0 -0.707107 0" type="capsule" rgba="0.8 0.2 0.1 1"/>
                                                <!-- Add sides for tendon to pass through-->
                                                <site name="cable_21_y_front" pos="0 0.005 0"/> 
                                                <site name="cable_21_y_back" pos="0 -0.005 0"/>
                                                <site name="cable_21_z_front" pos="0 0 0.005"/> 
                                                <site name="cable_21_z_back" pos="0 0 -0.005"/> 
                                                <plugin instance="compositeactuated"/>
                                                <body name="actuatedB_22" pos="0.01 0 0">
                                                  <joint name="actuatedJ_22" pos="0 0 0" type="ball" group="3" actuatorfrclimited="false" armature="0.01" damping="0.25"/>
                                                  <geom name="actuatedG22" size="0.005 0.005" pos="0.005 0 0" quat="0.707107 0 -0.707107 0" type="capsule" rgba="0.8 0.2 0.1 1"/>
                                                  <!-- Add sides for tendon to pass through-->
                                                  <site name="cable_22_y_front" pos="0 0.005 0"/> 
                                                  <site name="cable_22_y_back" pos="0 -0.005 0"/>
                                                  <site name="cable_22_z_front" pos="0 0 0.005"/> 
                                                  <site name="cable_22_z_back" pos="0 0 -0.005"/> 
                                                  <plugin instance="compositeactuated"/>
                                                  <body name="actuatedB_23" pos="0.00999999 0 0">
                                                    <joint name="actuatedJ_23" pos="0 0 0" type="ball" group="3" actuatorfrclimited="false" armature="0.01" damping="0.25"/>
                                                    <geom name="actuatedG23" size="0.005 0.01" pos="0.01 0 0" quat="0.707107 0 -0.707107 0" type="capsule" rgba="0.8 0.2 0.1 1"/>
                                                    <!-- Add sides for tendon to pass through-->
                                                    <site name="cable_23_y_front" pos="0 0.005 0"/> 
                                                    <site name="cable_23_y_back" pos="0 -0.005 0"/>
                                                    <site name="cable_23_z_front" pos="0 0 0.005"/> 
                                                    <site name="cable_23_z_back" pos="0 0 -0.005"/> 
                                                    <plugin instance="compositeactuated"/>
                                                    <body name="actuatedB_24" pos="0.02 0 0">
                                                      <joint name="actuatedJ_24" pos="0 0 0" type="ball" group="3" actuatorfrclimited="false" armature="0.01" damping="0.25"/>
                                                      <geom name="actuatedG24" size="0.005 0.005" pos="0.005 0 0" quat="0.707107 0 -0.707107 0" type="capsule" rgba="0.8 0.2 0.1 1"/>
                                                      <!-- Add sides for tendon to pass through-->
                                                      <site name="cable_24_y_front" pos="0 0.005 0"/> 
                                                      <site name="cable_24_y_back" pos="0 -0.005 0"/>
                                                      <site name="cable_24_z_front" pos="0 0 0.005"/> 
                                                      <site name="cable_24_z_back" pos="0 0 -0.005"/> 
                                                      <plugin instance="compositeactuated"/>
                                                      <body name="actuatedB_25" pos="0.00999999 0 0">
                                                        <joint name="actuatedJ_25" pos="0 0 0" type="ball" group="3" actuatorfrclimited="false" armature="0.01" damping="0.25"/>
                                                        <geom name="actuatedG25" size="0.005 0.005" pos="0.005 0 0" quat="0.707107 0 -0.707107 0" type="capsule" rgba="0.8 0.2 0.1 1"/>
                                                        <!-- Add sides for tendon to pass through-->
                                                        <site name="cable_25_y_front" pos="0 0.005 0"/> 
                                                        <site name="cable_25_y_back" pos="0 -0.005 0"/>
                                                        <site name="cable_25_z_front" pos="0 0 0.005"/> 
                                                        <site name="cable_25_z_back" pos="0 0 -0.005"/> 
                                                        <plugin instance="compositeactuated"/>
                                                        <body name="actuatedB_26" pos="0.00999999 0 0">
                                                          <joint name="actuatedJ_26" pos="0 0 0" type="ball" group="3" actuatorfrclimited="false" armature="0.01" damping="0.25"/>
                                                          <geom name="actuatedG26" size="0.005 0.01" pos="0.01 0 0" quat="0.707107 0 -0.707107 0" type="capsule" rgba="0.8 0.2 0.1 1"/>
                                                          <!-- Add sides for tendon to pass through-->
                                                          <site name="cable_26_y_front" pos="0 0.005 0"/> 
                                                          <site name="cable_26_y_back" pos="0 -0.005 0"/>
                                                          <site name="cable_26_z_front" pos="0 0 0.005"/> 
                                                          <site name="cable_26_z_back" pos="0 0 -0.005"/> 
                                                          <plugin instance="compositeactuated"/>
                                                          <body name="actuatedB_27" pos="0.02 0 0">
                                                            <joint name="actuatedJ_27" pos="0 0 0" type="ball" group="3" actuatorfrclimited="false" armature="0.01" damping="0.25"/>
                                                            <geom name="actuatedG27" size="0.005 0.005" pos="0.005 0 0" quat="0.707107 0 -0.707107 0" type="capsule" rgba="0.8 0.2 0.1 1"/>
                                                            <!-- Add sides for tendon to pass through-->
                                                            <site name="cable_27_y_front" pos="0 0.005 0"/> 
                                                            <site name="cable_27_y_back" pos="0 -0.005 0"/>
                                                            <site name="cable_27_z_front" pos="0 0 0.005"/> 
                                                            <site name="cable_27_z_back" pos="0 0 -0.005"/> 
                                                            <plugin instance="compositeactuated"/>
                                                            <body name="actuatedB_28" pos="0.00999999 0 0">
                                                              <joint name="actuatedJ_28" pos="0 0 0" type="ball" group="3" actuatorfrclimited="false" armature="0.01" damping="0.25"/>
                                                              <geom name="actuatedG28" size="0.005 0.005" pos="0.005 0 0" quat="0.707107 0 -0.707107 0" type="capsule" rgba="0.8 0.2 0.1 1"/>
                                                              <!-- Add sides for tendon to pass through-->
                                                              <site name="cable_28_y_front" pos="0 0.005 0"/> 
                                                              <site name="cable_28_y_back" pos="0 -0.005 0"/>
                                                              <site name="cable_28_z_front" pos="0 0 0.005"/> 
                                                              <site name="cable_28_z_back" pos="0 0 -0.005"/> 
                                                              <plugin instance="compositeactuated"/>
                                                              <body name="actuatedB_29" pos="0.00999999 0 0">
                                                                <joint name="actuatedJ_29" pos="0 0 0" type="ball" group="3" actuatorfrclimited="false" armature="0.01" damping="0.25"/>
                                                                <geom name="actuatedG29" size="0.005 0.00500001" pos="0.00500001 0 0" quat="0.707107 0 -0.707107 0" type="capsule" rgba="0.8 0.2 0.1 1"/>
                                                                <!-- Add sides for tendon to pass through-->
                                                                <site name="cable_29_y_front" pos="0 0.005 0"/> 
                                                                <site name="cable_29_y_back" pos="0 -0.005 0"/>
                                                                <site name="cable_29_z_front" pos="0 0 0.005"/> 
                                                                <site name="cable_29_z_back" pos="0 0 -0.005"/> 
                                                                <plugin instance="compositeactuated"/>
                                                                <body name="actuatedB_30" pos="0.01 0 0">
                                                                  <joint name="actuatedJ_30" pos="0 0 0" type="ball" group="3" actuatorfrclimited="false" armature="0.01" damping="0.25"/>
                                                                  <geom name="actuatedG30" size="0.005 0.00999999" pos="0.00999999 0 0" quat="0.707107 0 -0.707107 0" type="capsule" rgba="0.8 0.2 0.1 1"/>
                                                                  <!-- Add sides for tendon to pass through-->
                                                                  <site name="cable_30_y_front" pos="0 0.005 0"/> 
                                                                  <site name="cable_30_y_back" pos="0 -0.005 0"/>
                                                                  <site name="cable_30_z_front" pos="0 0 0.005"/> 
                                                                  <site name="cable_30_z_back" pos="0 0 -0.005"/>
                                                                  <plugin instance="compositeactuated"/>
                                                                  <body name="actuatedB_31" pos="0.02 0 0">
                                                                    <joint name="actuatedJ_31" pos="0 0 0" type="ball" group="3" actuatorfrclimited="false" armature="0.01" damping="0.25"/>
                                                                    <geom name="actuatedG31" size="0.005 0.00500001" pos="0.00500001 0 0" quat="0.707107 0 -0.707107 0" type="capsule" rgba="0.8 0.2 0.1 1"/>
                                                                    <!-- Add sides for tendon to pass through-->
                                                                    <site name="cable_31_y_front" pos="0 0.005 0"/> 
                                                                    <site name="cable_31_y_back" pos="0 -0.005 0"/>
                                                                    <site name="cable_31_z_front" pos="0 0 0.005"/> 
                                                                    <site name="cable_31_z_back" pos="0 0 -0.005"/>
                                                                    <plugin instance="compositeactuated"/>
                                                                    <body name="actuatedB_32" pos="0.01 0 0">
                                                                      <joint name="actuatedJ_32" pos="0 0 0" type="ball" group="3" actuatorfrclimited="false" armature="0.01" damping="0.25"/>
                                                                      <geom name="actuatedG32" size="0.005 0.005" pos="0.005 0 0" quat="0.707107 0 -0.707107 0" type="capsule" rgba="0.8 0.2 0.1 1"/>
                                                                      <!-- Add sides for tendon to pass through-->
                                                                      <site name="cable_32_y_front" pos="0 0.005 0"/> 
                                                                      <site name="cable_32_y_back" pos="0 -0.005 0"/>
                                                                      <site name="cable_32_z_front" pos="0 0 0.005"/> 
                                                                      <site name="cable_32_z_back" pos="0 0 -0.005"/>
                                                                      <plugin instance="compositeactuated"/>
                                                                      <body name="actuatedB_33" pos="0.00999999 0 0">
                                                                        <joint name="actuatedJ_33" pos="0 0 0" type="ball" group="3" actuatorfrclimited="false" armature="0.01" damping="0.25"/>
                                                                        <geom name="actuatedG33" size="0.005 0.01" pos="0.01 0 0" quat="0.707107 0 -0.707107 0" type="capsule" rgba="0.8 0.2 0.1 1"/>
                                                                        <!-- Add sides for tendon to pass through-->
                                                                        <site name="cable_33_y_front" pos="0 0.005 0"/> 
                                                                        <site name="cable_33_y_back" pos="0 -0.005 0"/>
                                                                        <site name="cable_33_z_front" pos="0 0 0.005"/> 
                                                                        <site name="cable_33_z_back" pos="0 0 -0.005"/>
                                                                        <plugin instance="compositeactuated"/>
                                                                        <body name="actuatedB_34" pos="0.02 0 0">
                                                                          <joint name="actuatedJ_34" pos="0 0 0" type="ball" group="3" actuatorfrclimited="false" armature="0.01" damping="0.25"/>
                                                                          <geom name="actuatedG34" size="0.005 0.005" pos="0.005 0 0" quat="0.707107 0 -0.707107 0" type="capsule" rgba="0.8 0.2 0.1 1"/>
                                                                          <!-- Add sides for tendon to pass through-->
                                                                          <site name="cable_34_y_front" pos="0 0.005 0"/> 
                                                                          <site name="cable_34_y_back" pos="0 -0.005 0"/>
                                                                          <site name="cable_34_z_front" pos="0 0 0.005"/> 
                                                                          <site name="cable_34_z_back" pos="0 0 -0.005"/>
                                                                          <plugin instance="compositeactuated"/>
                                                                          <body name="actuatedB_35" pos="0.00999999 0 0">
                                                                            <joint name="actuatedJ_35" pos="0 0 0" type="ball" group="3" actuatorfrclimited="false" armature="0.01" damping="0.25"/>
                                                                            <geom name="actuatedG35" size="0.005 0.005" pos="0.005 0 0" quat="0.707107 0 -0.707107 0" type="capsule" rgba="0.8 0.2 0.1 1"/>
                                                                            <!-- Add sides for tendon to pass through-->
                                                                            <site name="cable_35_y_front" pos="0 0.005 0"/> 
                                                                            <site name="cable_35_y_back" pos="0 -0.005 0"/>
                                                                            <site name="cable_35_z_front" pos="0 0 0.005"/> 
                                                                            <site name="cable_35_z_back" pos="0 0 -0.005"/>
                                                                            <plugin instance="compositeactuated"/>
                                                                            <body name="actuatedB_36" pos="0.01 0 0">
                                                                              <joint name="actuatedJ_36" pos="0 0 0" type="ball" group="3" actuatorfrclimited="false" armature="0.01" damping="0.25"/>
                                                                              <geom name="actuatedG36" size="0.005 0.005" pos="0.005 0 0" quat="0.707107 0 -0.707107 0" type="capsule" rgba="0.8 0.2 0.1 1"/>
                                                                              <!-- Add sides for tendon to pass through-->
                                                                              <site name="cable_36_y_front" pos="0 0.005 0"/> 
                                                                              <site name="cable_36_y_back" pos="0 -0.005 0"/>
                                                                              <site name="cable_36_z_front" pos="0 0 0.005"/> 
                                                                              <site name="cable_36_z_back" pos="0 0 -0.005"/>
                                                                              <plugin instance="compositeactuated"/>
                                                                              <body name="actuatedB_37" pos="0.00999999 0 0">
                                                                                <joint name="actuatedJ_37" pos="0 0 0" type="ball" group="3" actuatorfrclimited="false" armature="0.01" damping="0.25"/>
                                                                                <geom name="actuatedG37" size="0.005 0.01" pos="0.01 0 0" quat="0.707107 0 -0.707107 0" type="capsule" rgba="0.8 0.2 0.1 1"/>
                                                                                <!-- Add sides for tendon to pass through-->
                                                                                <site name="cable_37_y_front" pos="0 0.005 0"/> 
                                                                                <site name="cable_37_y_back" pos="0 -0.005 0"/>
                                                                                <site name="cable_37_z_front" pos="0 0 0.005"/> 
                                                                                <site name="cable_37_z_back" pos="0 0 -0.005"/>
                                                                                <plugin instance="compositeactuated"/>
                                                                                <body name="actuatedB_last" pos="0.02 0 0">
                                                                                  <joint name="actuatedJ_last" pos="0 0 0" type="ball" group="3" actuatorfrclimited="false" armature="0.01" damping="0.25"/>
                                                                                  <geom name="actuatedG38" size="0.005 0.005" pos="0.005 0 0" quat="0.707107 0 -0.707107 0" type="capsule" rgba="0.8 0.2 0.1 1"/>
                                                                                  <!-- Add sides for tendon to pass through-->
                                                                                  <site name="cable_38_y_front" pos="0 0.005 0"/> 
                                                                                  <site name="cable_38_y_back" pos="0 -0.005 0"/>
                                                                                  <site name="cable_38_z_front" pos="0 0 0.005"/> 
                                                                                  <site name="cable_38_z_back" pos="0 0 -0.005"/> 
                                                                                  <site name="endeffector" pos="0.015 0 0"/> 
                                                                                  <plugin instance="compositeactuated"/>
                                                                                </body>
                                                                              </body>
                                                                            </body>
                                                                          </body>
                                                                        </body>
                                                                      </body>
                                                                    </body>
                                                                  </body>
                                                                </body>
                                                              </body>
                                                            </body>
                                                          </body>
                                                        </body>
                                                      </body>
                                                    </body>
                                                  </body>
                                                </body>
                                              </body>
                                            </body>
                                          </body>
                                        </body>
                                      </body>
                                    </body>
                                  </body>
                                </body>
                              </body>
                            </body>
                          </body>
                        </body>
                      </body>
                    </body>
                  </body>
                </body>
              </body>
            </body>
          </body>
        </body>
      </body>
    </body>
  </worldbody>
  <!-- add tendons attached to trunk-->
  <!-- tendons attached to end of trunk-->
  <tendon>
    <spatial name="tendon_y_front_end" stiffness="1.0" damping="2.0" width="0.002">
        <site site="cable_0_y_front"/>
        <site site="cable_1_y_front"/>
        <site site="cable_2_y_front"/>
        <site site="cable_3_y_front"/>
        <site site="cable_4_y_front"/>
        <site site="cable_5_y_front"/>
        <site site="cable_6_y_front"/>
        <site site="cable_7_y_front"/>
        <site site="cable_8_y_front"/>
        <site site="cable_9_y_front"/>
        <site site="cable_10_y_front"/>
        <site site="cable_11_y_front"/>
        <site site="cable_12_y_front"/>
        <site site="cable_13_y_front"/>
        <site site="cable_14_y_front"/>
        <site site="cable_15_y_front"/>
        <site site="cable_16_y_front"/>
        <site site="cable_17_y_front"/>
        <site site="cable_18_y_front"/>
        <site site="cable_19_y_front"/>
        <site site="cable_20_y_front"/>
        <site site="cable_21_y_front"/>
        <site site="cable_22_y_front"/>
        <site site="cable_23_y_front"/>
        <site site="cable_24_y_front"/>
        <site site="cable_25_y_front"/>
        <site site="cable_26_y_front"/>
        <site site="cable_27_y_front"/>
        <site site="cable_28_y_front"/>
        <site site="cable_29_y_front"/>
        <site site="cable_30_y_front"/>
        <site site="cable_31_y_front"/>
        <site site="cable_32_y_front"/>
        <site site="cable_33_y_front"/>
        <site site="cable_34_y_front"/>
        <site site="cable_35_y_front"/>
        <site site="cable_36_y_front"/>
        <site site="cable_37_y_front"/>
        <site site="cable_38_y_front"/>
    </spatial>
  </tendon>
  <tendon>
    <spatial name="tendon_y_back_end" stiffness="1.0" damping="2.0" width="0.002">
        <site site="cable_0_y_back"/>
        <site site="cable_1_y_back"/>
        <site site="cable_2_y_back"/>
        <site site="cable_3_y_back"/>
        <site site="cable_4_y_back"/>
        <site site="cable_5_y_back"/>
        <site site="cable_6_y_back"/>
        <site site="cable_7_y_back"/>
        <site site="cable_8_y_back"/>
        <site site="cable_9_y_back"/>
        <site site="cable_10_y_back"/>
        <site site="cable_11_y_back"/>
        <site site="cable_12_y_back"/>
        <site site="cable_13_y_back"/>
        <site site="cable_14_y_back"/>
        <site site="cable_15_y_back"/>
        <site site="cable_16_y_back"/>
        <site site="cable_17_y_back"/>
        <site site="cable_18_y_back"/>
        <site site="cable_19_y_back"/>
        <site site="cable_20_y_back"/>
        <site site="cable_21_y_back"/>
        <site site="cable_22_y_back"/>
        <site site="cable_23_y_back"/>
        <site site="cable_24_y_back"/>
        <site site="cable_25_y_back"/>
        <site site="cable_26_y_back"/>
        <site site="cable_27_y_back"/>
        <site site="cable_28_y_back"/>
        <site site="cable_29_y_back"/>
        <site site="cable_30_y_back"/>
        <site site="cable_31_y_back"/>
        <site site="cable_32_y_back"/>
        <site site="cable_33_y_back"/>
        <site site="cable_34_y_back"/>
        <site site="cable_35_y_back"/>
        <site site="cable_36_y_back"/>
        <site site="cable_37_y_back"/>
        <site site="cable_38_y_back"/>
    </spatial>
  </tendon>
  <tendon>
    <spatial name="tendon_z_front_end" stiffness="1.0" damping="2.0" width="0.002">
        <site site="cable_0_z_front"/>
        <site site="cable_1_z_front"/>
        <site site="cable_2_z_front"/>
        <site site="cable_3_z_front"/>
        <site site="cable_4_z_front"/>
        <site site="cable_5_z_front"/>
        <site site="cable_6_z_front"/>
        <site site="cable_7_z_front"/>
        <site site="cable_8_z_front"/>
        <site site="cable_9_z_front"/>
        <site site="cable_10_z_front"/>
        <site site="cable_11_z_front"/>
        <site site="cable_12_z_front"/>
        <site site="cable_13_z_front"/>
        <site site="cable_14_z_front"/>
        <site site="cable_15_z_front"/>
        <site site="cable_16_z_front"/>
        <site site="cable_17_z_front"/>
        <site site="cable_18_z_front"/>
        <site site="cable_19_z_front"/>
        <site site="cable_20_z_front"/>
        <site site="cable_21_z_front"/>
        <site site="cable_22_z_front"/>
        <site site="cable_23_z_front"/>
        <site site="cable_24_z_front"/>
        <site site="cable_25_z_front"/>
        <site site="cable_26_z_front"/>
        <site site="cable_27_z_front"/>
        <site site="cable_28_z_front"/>
        <site site="cable_29_z_front"/>
        <site site="cable_30_z_front"/>
        <site site="cable_31_z_front"/>
        <site site="cable_32_z_front"/>
        <site site="cable_33_z_front"/>
        <site site="cable_34_z_front"/>
        <site site="cable_35_z_front"/>
        <site site="cable_36_z_front"/>
        <site site="cable_37_z_front"/>
        <site site="cable_38_z_front"/>
    </spatial>
  </tendon>
  <tendon>
    <spatial name="tendon_z_back_end" stiffness="1.0" damping="2.0" width="0.002">
        <site site="cable_0_z_back"/>
        <site site="cable_1_z_back"/>
        <site site="cable_2_z_back"/>
        <site site="cable_3_z_back"/>
        <site site="cable_4_z_back"/>
        <site site="cable_5_z_back"/>
        <site site="cable_6_z_back"/>
        <site site="cable_7_z_back"/>
        <site site="cable_8_z_back"/>
        <site site="cable_9_z_back"/>
        <site site="cable_10_z_back"/>
        <site site="cable_11_z_back"/>
        <site site="cable_12_z_back"/>
        <site site="cable_13_z_back"/>
        <site site="cable_14_z_back"/>
        <site site="cable_15_z_back"/>
        <site site="cable_16_z_back"/>
        <site site="cable_17_z_back"/>
        <site site="cable_18_z_back"/>
        <site site="cable_19_z_back"/>
        <site site="cable_20_z_back"/>
        <site site="cable_21_z_back"/>
        <site site="cable_22_z_back"/>
        <site site="cable_23_z_back"/>
        <site site="cable_24_z_back"/>
        <site site="cable_25_z_back"/>
        <site site="cable_26_z_back"/>
        <site site="cable_27_z_back"/>
        <site site="cable_28_z_back"/>
        <site site="cable_29_z_back"/>
        <site site="cable_30_z_back"/>
        <site site="cable_31_z_back"/>
        <site site="cable_32_z_back"/>
        <site site="cable_33_z_back"/>
        <site site="cable_34_z_back"/>
        <site site="cable_35_z_back"/>
        <site site="cable_36_z_back"/>
        <site site="cable_37_z_back"/>
        <site site="cable_38_z_back"/>
    </spatial>
  </tendon>
  <!-- Muscles actuating tendons-->
  <actuator>
    <muscle tendon="tendon_y_front_end"/>
    <muscle tendon="tendon_y_back_end"/>
    <muscle tendon="tendon_z_front_end"/>
    <muscle tendon="tendon_z_back_end"/>
  </actuator>
  <contact>
    <exclude body1="actuatedB_first" body2="actuatedB_1"/>
    <exclude body1="actuatedB_1" body2="actuatedB_2"/>
    <exclude body1="actuatedB_2" body2="actuatedB_3"/>
    <exclude body1="actuatedB_3" body2="actuatedB_4"/>
    <exclude body1="actuatedB_4" body2="actuatedB_5"/>
    <exclude body1="actuatedB_5" body2="actuatedB_6"/>
    <exclude body1="actuatedB_6" body2="actuatedB_7"/>
    <exclude body1="actuatedB_7" body2="actuatedB_8"/>
    <exclude body1="actuatedB_8" body2="actuatedB_9"/>
    <exclude body1="actuatedB_9" body2="actuatedB_10"/>
    <exclude body1="actuatedB_10" body2="actuatedB_11"/>
    <exclude body1="actuatedB_11" body2="actuatedB_12"/>
    <exclude body1="actuatedB_12" body2="actuatedB_13"/>
    <exclude body1="actuatedB_13" body2="actuatedB_14"/>
    <exclude body1="actuatedB_14" body2="actuatedB_15"/>
    <exclude body1="actuatedB_15" body2="actuatedB_16"/>
    <exclude body1="actuatedB_16" body2="actuatedB_17"/>
    <exclude body1="actuatedB_17" body2="actuatedB_18"/>
    <exclude body1="actuatedB_18" body2="actuatedB_19"/>
    <exclude body1="actuatedB_19" body2="actuatedB_20"/>
    <exclude body1="actuatedB_20" body2="actuatedB_21"/>
    <exclude body1="actuatedB_21" body2="actuatedB_22"/>
    <exclude body1="actuatedB_22" body2="actuatedB_23"/>
    <exclude body1="actuatedB_23" body2="actuatedB_24"/>
    <exclude body1="actuatedB_24" body2="actuatedB_25"/>
    <exclude body1="actuatedB_25" body2="actuatedB_26"/>
    <exclude body1="actuatedB_26" body2="actuatedB_27"/>
    <exclude body1="actuatedB_27" body2="actuatedB_28"/>
    <exclude body1="actuatedB_28" body2="actuatedB_29"/>
    <exclude body1="actuatedB_29" body2="actuatedB_30"/>
    <exclude body1="actuatedB_30" body2="actuatedB_31"/>
    <exclude body1="actuatedB_31" body2="actuatedB_32"/>
    <exclude body1="actuatedB_32" body2="actuatedB_33"/>
    <exclude body1="actuatedB_33" body2="actuatedB_34"/>
    <exclude body1="actuatedB_34" body2="actuatedB_35"/>
    <exclude body1="actuatedB_35" body2="actuatedB_36"/>
    <exclude body1="actuatedB_36" body2="actuatedB_37"/>
    <exclude body1="actuatedB_37" body2="actuatedB_last"/>
  </contact>
</mujoco>